Workbook

Sheet Leia-me
A1: Kodoo — guia do roadmap revisado
A3: Princípio | B3: Roadmap alinhado às fases do repositório bootstrapprx/kodoo, separado do inventário legado de telas/funções.
A4: Fonte de verdade | B4: context/roadmap.md define F0–F6 e A1; context/domain-app-migration.md e context/application-architecture.md refinam o estado contábil e as aplicações.
A5: Como usar | B5: Comece pela aba Roadmap. Mude Estado inicial/Estado atual apenas após conferir código, testes e documentação. Registre evidências clicáveis ou comandos reproduzíveis.
A6: Importante | B6: Os status da planilha original não foram confirmados contra o código; foram preservados como dados legados e rotulados explicitamente como não verificados.
A7: Fases | B7: A aba Fases contém a taxonomia do repositório. F0–F6 não devem ser interpretadas como as fases antigas da planilha.
A8: Inventário — Telas | B8: O catálogo original foi preservado. A coluna Fase catálogo antigo mantém o valor anterior; preencha Fase Kodoo (reclassificar) após análise individual.
A9: Inventário — Funções | B9: O catálogo original foi preservado. A coluna Fase catálogo antigo mantém o valor anterior; preencha Fase Kodoo (reclassificar) após análise individual.
A10: Gates de aceite | B10: Checklist transversal de definição de pronto. Aplique por capacidade e marque N/A com justificativa quando uma superfície não se aplicar.
A11: Auditoria | B11: Registra os principais riscos de planejamento encontrados ao comparar a planilha com a documentação do repositório.
A12: Limite desta versão | B12: É uma revisão documental, não uma auditoria completa de cada linha de código. Estados iniciais são hipóteses baseadas nos documentos consultados; valide contra o HEAD atual.
A13: Repositório | B13: https://github.com/bootstrapprx/kodoo
A14: Documentos principais | B14: https://github.com/bootstrapprx/kodoo/blob/main/context/roadmap.md
... A27: Health (inventários) | B27: ⚠ lacuna de evidência/código · ◐ proprietário pendente · ○ sem relações em Dependencies · ✔ OK.

Sheet Painel
A1: Kodoo — painel de acompanhamento
A2: Tudo aqui é calculado por fórmulas a partir das outras abas — não edite o Painel. Atualize Current Status (Roadmap), Implementation Status (definições), Dependencies e Gates; os números e gráficos acompanham.
A4: ITENS DO ROADMAP | B4: % ROADMAP CONCLUÍDO | D4: P0 AINDA ABERTOS | F4: GATES DE ACEITE ATENDIDOS | H4: Como ler • Roadmap, gates e definições começam em "A validar"/"Planned": é um estado honesto, não uma falha. • Sem prova (código, teste, CI) o status não sobe. • Alertas ⚠ aparecem nos inventários (coluna Health).
A5: =COUNTA(Roadmap!$A$6:$A$200) | B5: =IFERROR(COUNTIF(Roadmap!$M$6:$M$200,"Concluído")/(COUNTA(Roadmap!$A$6:$A$200)-COUNTIF(Roadmap!$M$6:$M$200,"Não se aplica")),0) | D5: =COUNTIFS(Roadmap!$F$6:$F$200,"P0",Roadmap!$M$6:$M$200,"<>Concluído") | F5: =IFERROR(COUNTIF('Gates de aceite'!$E$6:$E$18,"Concluído")/(COUNTA('Gates de aceite'!$E$6:$E$18)-COUNTIF('Gates de aceite'!$E$6:$E$18,"Não se aplica")),0)
A6: =COUNTIF(Roadmap!$M$6:$M$200,"Concluído")&" concluídos" | B6: =COUNTIF(Roadmap!$M$6:$M$200,"Em andamento")&" em andamento" | D6: ="de "&COUNTIF(Roadmap!$F$6:$F$200,"P0")&" itens P0" | F6: =COUNTIF('Gates de aceite'!$E$6:$E$18,"Concluído")&" de "&COUNTA('Gates de aceite'!$E$6:$E$18)&" gates"
A8: DEFINIÇÕES CATALOGADAS | B8: % IMPLEMENTADAS / VERIFICADAS | D8: DECISÕES ABERTAS | F8: ALERTAS DE INTEGRIDADE
A9: =COUNTA('Constants & Enums'!$A$5:$A$200)+COUNTA('Metrics & Formulas'!$A$5:$A$200)+COUNTA('Projections & Dashboards'!$A$5:$A$200) | B9: =IFERROR((COUNTIF('Constants & Enums'!$I$5:$I$200,"Implemented")+COUNTIF('Metrics & Formulas'!$I$5:$I$200,"Implemented")+COUNTIF('Projections & Dashboards'!$I$5:$I$200,"Implemented")+COUNTIF('Constants & Enums'!$I$5:$I$200,"Verified")+COUNTIF('Metrics & Formulas'!$I$5:$I$200,"Verified")+COUNTIF('Projections & Dashboards'!$I$5:$I$200,"Verified"))/(COUNTA('Constants & Enums'!$A$5:$A$200)+COUNTA('Metrics & Formulas'!$A$5:$A$200)+COUNTA('Projections & Dashboards'!$A$5:$A$200)),0) | D9: =COUNTIF('Decisões pendentes'!$H$5:$H$104,"Aberta") | F9: =COUNTIF(Dependencies!$I$5:$I$300,"✖*")+COUNTIF('Constants & Enums'!$T$5:$T$200,"⚠*")+COUNTIF('Metrics & Formulas'!$T$5:$T$200,"⚠*")+COUNTIF('Projections & Dashboards'!$T$5:$T$200,"⚠*")
A10: ="constantes, métricas, projeções e dashboards" | B10: ="Verified: "&(COUNTIF('Constants & Enums'!$I$5:$I$200,"Verified")+COUNTIF('Metrics & Formulas'!$I$5:$I$200,"Verified")+COUNTIF('Projections & Dashboards'!$I$5:$I$200,"Verified")) | D10: ="proprietários / localização pendentes" | F10: ="IDs inexistentes, sem link ou sem evidência"
A12: 1 · Roadmap por fase e estado | M12: 2 · Gates de aceite por estado
A13: Fase | B13: A validar | C13: Não iniciado | D13: Em andamento | E13: Parcial | F13: Concluído | G13: Bloqueado | H13: Não se aplica | I13: Total | J13: % concluído | M13: Estado | N13: Gates | O13: %
A14: F0 | B14: =COUNTIFS(Roadmap!$B$6:$B$200,$A14,Roadmap!$M$6:$M$200,B$13) | C14: =COUNTIFS(Roadmap!$B$6:$B$200,$A14,Roadmap!$M$6:$M$200,C$13) | D14: =COUNTIFS(Roadmap!$B$6:$B$200,$A14,Roadmap!$M$6:$M$200,D$13) | E14: =COUNTIFS(Roadmap!$B$6:$B$200,$A14,Roadmap!$M$6:$M$200,E$13) | F14: =COUNTIFS(Roadmap!$B$6:$B$200,$A14,Roadmap!$M$6:$M$200,F$13) | G14: =COUNTIFS(Roadmap!$B$6:$B$200,$A14,Roadmap!$M$6:$M$200,G$13) | H14: =COUNTIFS(Roadmap!$B$6:$B$200,$A14,Roadmap!$M$6:$M$200,H$13) | I14: =SUM(B14:H14) | J14: =IFERROR(F14/(I14-H14),0) | M14: A validar | N14: =COUNTIF('Gates de aceite'!$E$6:$E$18,M14) | O14: =IFERROR(N14/N$20,0)
A15: F1 | B15: =COUNTIFS(Roadmap!$B$6:$B$200,$A15,Roadmap!$M$6:$M$200,B$13) | C15: =COUNTIFS(Roadmap!$B$6:$B$200,$A15,Roadmap!$M$6:$M$200,C$13) | D15: =COUNTIFS(Roadmap!$B$6:$B$200,$A15,Roadmap!$M$6:$M$200,D$13) | E15: =COUNTIFS(Roadmap!$B$6:$B$200,$A15,Roadmap!$M$6:$M$200,E$13) | F15: =COUNTIFS(Roadmap!$B$6:$B$200,$A15,Roadmap!$M$6:$M$200,F$13) | G15: =COUNTIFS(Roadmap!$B$6:$B$200,$A15,Roadmap!$M$6:$M$200,G$13) | H15: =COUNTIFS(Roadmap!$B$6:$B$200,$A15,Roadmap!$M$6:$M$200,H$13) | I15: =SUM(B15:H15) | J15: =IFERROR(F15/(I15-H15),0) | M15: Não iniciado | N15: =COUNTIF('Gates de aceite'!$E$6:$E$18,M15) | O15: =IFERROR(N15/N$20,0)
A16: F2 | B16: =COUNTIFS(Roadmap!$B$6:$B$200,$A16,Roadmap!$M$6:$M$200,B$13) | C16: =COUNTIFS(Roadmap!$B$6:$B$200,$A16,Roadmap!$M$6:$M$200,C$13) | D16: =COUNTIFS(Roadmap!$B$6:$B$200,$A16,Roadmap!$M$6:$M$200,D$13) | E16: =COUNTIFS(Roadmap!$B$6:$B$200,$A16,Roadmap!$M$6:$M$200,E$13) | F16: =COUNTIFS(Roadmap!$B$6:$B$200,$A16,Roadmap!$M$6:$M$200,F$13) | G16: =COUNTIFS(Roadmap!$B$6:$B$200,$A16,Roadmap!$M$6:$M$200,G$13) | H16: =COUNTIFS(Roadmap!$B$6:$B$200,$A16,Roadmap!$M$6:$M$200,H$13) | I16: =SUM(B16:H16) | J16: =IFERROR(F16/(I16-H16),0) | M16: Em andamento | N16: =COUNTIF('Gates de aceite'!$E$6:$E$18,M16) | O16: =IFERROR(N16/N$20,0)
A17: F3 | B17: =COUNTIFS(Roadmap!$B$6:$B$200,$A17,Roadmap!$M$6:$M$200,B$13) | C17: =COUNTIFS(Roadmap!$B$6:$B$200,$A17,Roadmap!$M$6:$M$200,C$13) | D17: =COUNTIFS(Roadmap!$B$6:$B$200,$A17,Roadmap!$M$6:$M$200,D$13) | E17: =COUNTIFS(Roadmap!$B$6:$B$200,$A17,Roadmap!$M$6:$M$200,E$13) | F17: =COUNTIFS(Roadmap!$B$6:$B$200,$A17,Roadmap!$M$6:$M$200,F$13) | G17: =COUNTIFS(Roadmap!$B$6:$B$200,$A17,Roadmap!$M$6:$M$200,G$13) | H17: =COUNTIFS(Roadmap!$B$6:$B$200,$A17,Roadmap!$M$6:$M$200,H$13) | I17: =SUM(B17:H17) | J17: =IFERROR(F17/(I17-H17),0) | M17: Concluído | N17: =COUNTIF('Gates de aceite'!$E$6:$E$18,M17) | O17: =IFERROR(N17/N$20,0)
A18: F4 | B18: =COUNTIFS(Roadmap!$B$6:$B$200,$A18,Roadmap!$M$6:$M$200,B$13) | C18: =COUNTIFS(Roadmap!$B$6:$B$200,$A18,Roadmap!$M$6:$M$200,C$13) | D18: =COUNTIFS(Roadmap!$B$6:$B$200,$A18,Roadmap!$M$6:$M$200,D$13) | E18: =COUNTIFS(Roadmap!$B$6:$B$200,$A18,Roadmap!$M$6:$M$200,E$13) | F18: =COUNTIFS(Roadmap!$B$6:$B$200,$A18,Roadmap!$M$6:$M$200,F$13) | G18: =COUNTIFS(Roadmap!$B$6:$B$200,$A18,Roadmap!$M$6:$M$200,G$13) | H18: =COUNTIFS(Roadmap!$B$6:$B$200,$A18,Roadmap!$M$6:$M$200,H$13) | I18: =SUM(B18:H18) | J18: =IFERROR(F18/(I18-H18),0) | M18: Bloqueado | N18: =COUNTIF('Gates de aceite'!$E$6:$E$18,M18) | O18: =IFERROR(N18/N$20,0)
A19: F5 | B19: =COUNTIFS(Roadmap!$B$6:$B$200,$A19,Roadmap!$M$6:$M$200,B$13) | C19: =COUNTIFS(Roadmap!$B$6:$B$200,$A19,Roadmap!$M$6:$M$200,C$13) | D19: =COUNTIFS(Roadmap!$B$6:$B$200,$A19,Roadmap!$M$6:$M$200,D$13) | E19: =COUNTIFS(Roadmap!$B$6:$B$200,$A19,Roadmap!$M$6:$M$200,E$13) | F19: =COUNTIFS(Roadmap!$B$6:$B$200,$A19,Roadmap!$M$6:$M$200,F$13) | G19: =COUNTIFS(Roadmap!$B$6:$B$200,$A19,Roadmap!$M$6:$M$200,G$13) | H19: =COUNTIFS(Roadmap!$B$6:$B$200,$A19,Roadmap!$M$6:$M$200,H$13) | I19: =SUM(B19:H19) | J19: =IFERROR(F19/(I19-H19),0) | M19: Não se aplica | N19: =COUNTIF('Gates de aceite'!$E$6:$E$18,M19) | O19: =IFERROR(N19/N$20,0)
A20: F6 | B20: =COUNTIFS(Roadmap!$B$6:$B$200,$A20,Roadmap!$M$6:$M$200,B$13) | C20: =COUNTIFS(Roadmap!$B$6:$B$200,$A20,Roadmap!$M$6:$M$200,C$13) | D20: =COUNTIFS(Roadmap!$B$6:$B$200,$A20,Roadmap!$M$6:$M$200,D$13) | E20: =COUNTIFS(Roadmap!$B$6:$B$200,$A20,Roadmap!$M$6:$M$200,E$13) | F20: =COUNTIFS(Roadmap!$B$6:$B$200,$A20,Roadmap!$M$6:$M$200,F$13) | G20: =COUNTIFS(Roadmap!$B$6:$B$200,$A20,Roadmap!$M$6:$M$200,G$13) | H20: =COUNTIFS(Roadmap!$B$6:$B$200,$A20,Roadmap!$M$6:$M$200,H$13) | I20: =SUM(B20:H20) | J20: =IFERROR(F20/(I20-H20),0) | M20: Total | N20: =SUM(N14:N19) | O20: =SUM(O14:O19)
A21: A1 | B21: =COUNTIFS(Roadmap!$B$6:$B$200,$A21,Roadmap!$M$6:$M$200,B$13) | C21: =COUNTIFS(Roadmap!$B$6:$B$200,$A21,Roadmap!$M$6:$M$200,C$13) | D21: =COUNTIFS(Roadmap!$B$6:$B$200,$A21,Roadmap!$M$6:$M$200,D$13) | E21: =COUNTIFS(Roadmap!$B$6:$B$200,$A21,Roadmap!$M$6:$M$200,E$13) | F21: =COUNTIFS(Roadmap!$B$6:$B$200,$A21,Roadmap!$M$6:$M$200,F$13) | G21: =COUNTIFS(Roadmap!$B$6:$B$200,$A21,Roadmap!$M$6:$M$200,G$13) | H21: =COUNTIFS(Roadmap!$B$6:$B$200,$A21,Roadmap!$M$6:$M$200,H$13) | I21: =SUM(B21:H21) | J21: =IFERROR(F21/(I21-H21),0)
A22: Transversal | B22: =COUNTIFS(Roadmap!$B$6:$B$200,$A22,Roadmap!$M$6:$M$200,B$13) | C22: =COUNTIFS(Roadmap!$B$6:$B$200,$A22,Roadmap!$M$6:$M$200,C$13) | D22: =COUNTIFS(Roadmap!$B$6:$B$200,$A22,Roadmap!$M$6:$M$200,D$13) | E22: =COUNTIFS(Roadmap!$B$6:$B$200,$A22,Roadmap!$M$6:$M$200,E$13) | F22: =COUNTIFS(Roadmap!$B$6:$B$200,$A22,Roadmap!$M$6:$M$200,F$13) | G22: =COUNTIFS(Roadmap!$B$6:$B$200,$A22,Roadmap!$M$6:$M$200,G$13) | H22: =COUNTIFS(Roadmap!$B$6:$B$200,$A22,Roadmap!$M$6:$M$200,H$13) | I22: =SUM(B22:H22) | J22: =IFERROR(F22/(I22-H22),0)
A23: Total | B23: =SUM(B14:B22) | C23: =SUM(C14:C22) | D23: =SUM(D14:D22) | E23: =SUM(E14:E22) | F23: =SUM(F14:F22) | G23: =SUM(G14:G22) | H23: =SUM(H14:H22) | I23: =SUM(I14:I22) | J23: =IFERROR(F23/(I23-H23),0)
A44: 3 · Definições por tipo e status de implementação | M44: 4 · Definições por módulo pai
A45: Tipo | B45: Planned | C45: Partial | D45: Implemented | E45: Verified | F45: Total | G45: % impl./verif. | M45: Módulo pai | N45: Constants & Enums | O45: Metrics & Formulas | P45: Projections & Dashboards | Q45: Total
A46: DomainConstant | B46: =COUNTIFS('Constants & Enums'!$C$5:$C$200,$A46,'Constants & Enums'!$I$5:$I$200,B$45)+COUNTIFS('Metrics & Formulas'!$C$5:$C$200,$A46,'Metrics & Formulas'!$I$5:$I$200,B$45)+COUNTIFS('Projections & Dashboards'!$C$5:$C$200,$A46,'Projections & Dashboards'!$I$5:$I$200,B$45) | C46: =COUNTIFS('Constants & Enums'!$C$5:$C$200,$A46,'Constants & Enums'!$I$5:$I$200,C$45)+COUNTIFS('Metrics & Formulas'!$C$5:$C$200,$A46,'Metrics & Formulas'!$I$5:$I$200,C$45)+COUNTIFS('Projections & Dashboards'!$C$5:$C$200,$A46,'Projections & Dashboards'!$I$5:$I$200,C$45) | D46: =COUNTIFS('Constants & Enums'!$C$5:$C$200,$A46,'Constants & Enums'!$I$5:$I$200,D$45)+COUNTIFS('Metrics & Formulas'!$C$5:$C$200,$A46,'Metrics & Formulas'!$I$5:$I$200,D$45)+COUNTIFS('Projections & Dashboards'!$C$5:$C$200,$A46,'Projections & Dashboards'!$I$5:$I$200,D$45) | E46: =COUNTIFS('Constants & Enums'!$C$5:$C$200,$A46,'Constants & Enums'!$I$5:$I$200,E$45)+COUNTIFS('Metrics & Formulas'!$C$5:$C$200,$A46,'Metrics & Formulas'!$I$5:$I$200,E$45)+COUNTIFS('Projections & Dashboards'!$C$5:$C$200,$A46,'Projections & Dashboards'!$I$5:$I$200,E$45) | F46: =SUM(B46:E46) | G46: =IFERROR((D46+E46)/F46,0) | M46: =Listas!P5 | N46: =COUNTIF('Constants & Enums'!$D$5:$D$200,$M46) | O46: =COUNTIF('Metrics & Formulas'!$D$5:$D$200,$M46) | P46: =COUNTIF('Projections & Dashboards'!$D$5:$D$200,$M46) | Q46: =SUM(N46:P46)
A47: Enum | B47: =COUNTIFS('Constants & Enums'!$C$5:$C$200,$A47,'Constants & Enums'!$I$5:$I$200,B$45)+COUNTIFS('Metrics & Formulas'!$C$5:$C$200,$A47,'Metrics & Formulas'!$I$5:$I$200,B$45)+COUNTIFS('Projections & Dashboards'!$C$5:$C$200,$A47,'Projections & Dashboards'!$I$5:$I$200,B$45) | C47: =COUNTIFS('Constants & Enums'!$C$5:$C$200,$A47,'Constants & Enums'!$I$5:$I$200,C$45)+COUNTIFS('Metrics & Formulas'!$C$5:$C$200,$A47,'Metrics & Formulas'!$I$5:$I$200,C$45)+COUNTIFS('Projections & Dashboards'!$C$5:$C$200,$A47,'Projections & Dashboards'!$I$5:$I$200,C$45) | D47: =COUNTIFS('Constants & Enums'!$C$5:$C$200,$A47,'Constants & Enums'!$I$5:$I$200,D$45)+COUNTIFS('Metrics & Formulas'!$C$5:$C$200,$A47,'Metrics & Formulas'!$I$5:$I$200,D$45)+COUNTIFS('Projections & Dashboards'!$C$5:$C$200,$A47,'Projections & Dashboards'!$I$5:$I$200,D$45) | E47: =COUNTIFS('Constants & Enums'!$C$5:$C$200,$A47,'Constants & Enums'!$I$5:$I$200,E$45)+COUNTIFS('Metrics & Formulas'!$C$5:$C$200,$A47,'Metrics & Formulas'!$I$5:$I$200,E$45)+COUNTIFS('Projections & Dashboards'!$C$5:$C$200,$A47,'Projections & Dashboards'!$I$5:$I$200,E$45) | F47: =SUM(B47:E47) | G47: =IFERROR((D47+E47)/F47,0) | M47: =Listas!P6 | N47: =COUNTIF('Constants & Enums'!$D$5:$D$200,$M47) | O47: =COUNTIF('Metrics & Formulas'!$D$5:$D$200,$M47) | P47: =COUNTIF('Projections & Dashboards'!$D$5:$D$200,$M47) | Q47: =SUM(N47:P47)
A48: Policy | B48: =COUNTIFS('Constants & Enums'!$C$5:$C$200,$A48,'Constants & Enums'!$I$5:$I$200,B$45)+COUNTIFS('Metrics & Formulas'!$C$5:$C$200,$A48,'Metrics & Formulas'!$I$5:$I$200,B$45)+COUNTIFS('Projections & Dashboards'!$C$5:$C$200,$A48,'Projections & Dashboards'!$I$5:$I$200,B$45) | C48: =COUNTIFS('Constants & Enums'!$C$5:$C$200,$A48,'Constants & Enums'!$I$5:$I$200,C$45)+COUNTIFS('Metrics & Formulas'!$C$5:$C$200,$A48,'Metrics & Formulas'!$I$5:$I$200,C$45)+COUNTIFS('Projections & Dashboards'!$C$5:$C$200,$A48,'Projections & Dashboards'!$I$5:$I$200,C$45) | D48: =COUNTIFS('Constants & Enums'!$C$5:$C$200,$A48,'Constants & Enums'!$I$5:$I$200,D$45)+COUNTIFS('Metrics & Formulas'!$C$5:$C$200,$A48,'Metrics & Formulas'!$I$5:$I$200,D$45)+COUNTIFS('Projections & Dashboards'!$C$5:$C$200,$A48,'Projections & Dashboards'!$I$5:$I$200,D$45) | E48: =COUNTIFS('Constants & Enums'!$C$5:$C$200,$A48,'Constants & Enums'!$I$5:$I$200,E$45)+COUNTIFS('Metrics & Formulas'!$C$5:$C$200,$A48,'Metrics & Formulas'!$I$5:$I$200,E$45)+COUNTIFS('Projections & Dashboards'!$C$5:$C$200,$A48,'Projections & Dashboards'!$I$5:$I$200,E$45) | F48: =SUM(B48:E48) | G48: =IFERROR((D48+E48)/F48,0) | M48: =Listas!P7 | N48: =COUNTIF('Constants & Enums'!$D$5:$D$200,$M48) | O48: =COUNTIF('Metrics & Formulas'!$D$5:$D$200,$M48) | P48: =COUNTIF('Projections & Dashboards'!$D$5:$D$200,$M48) | Q48: =SUM(N48:P48)
A49: Metric | B49: =COUNTIFS('Constants & Enums'!$C$5:$C$200,$A49,'Constants & Enums'!$I$5:$I$200,B$45)+COUNTIFS('Metrics & Formulas'!$C$5:$C$200,$A49,'Metrics & Formulas'!$I$5:$I$200,B$45)+COUNTIFS('Projections & Dashboards'!$C$5:$C$200,$A49,'Projections & Dashboards'!$I$5:$I$200,B$45) | C49: =COUNTIFS('Constants & Enums'!$C$5:$C$200,$A49,'Constants & Enums'!$I$5:$I$200,C$45)+COUNTIFS('Metrics & Formulas'!$C$5:$C$200,$A49,'Metrics & Formulas'!$I$5:$I$200,C$45)+COUNTIFS('Projections & Dashboards'!$C$5:$C$200,$A49,'Projections & Dashboards'!$I$5:$I$200,C$45) | D49: =COUNTIFS('Constants & Enums'!$C$5:$C$200,$A49,'Constants & Enums'!$I$5:$I$200,D$45)+COUNTIFS('Metrics & Formulas'!$C$5:$C$200,$A49,'Metrics & Formulas'!$I$5:$I$200,D$45)+COUNTIFS('Projections & Dashboards'!$C$5:$C$200,$A49,'Projections & Dashboards'!$I$5:$I$200,D$45) | E49: =COUNTIFS('Constants & Enums'!$C$5:$C$200,$A49,'Constants & Enums'!$I$5:$I$200,E$45)+COUNTIFS('Metrics & Formulas'!$C$5:$C$200,$A49,'Metrics & Formulas'!$I$5:$I$200,E$45)+COUNTIFS('Projections & Dashboards'!$C$5:$C$200,$A49,'Projections & Dashboards'!$I$5:$I$200,E$45) | F49: =SUM(B49:E49) | G49: =IFERROR((D49+E49)/F49,0) | M49: =Listas!P8 | N49: =COUNTIF('Constants & Enums'!$D$5:$D$200,$M49) | O49: =COUNTIF('Metrics & Formulas'!$D$5:$D$200,$M49) | P49: =COUNTIF('Projections & Dashboards'!$D$5:$D$200,$M49) | Q49: =SUM(N49:P49)
A50: Projection | B50: =COUNTIFS('Constants & Enums'!$C$5:$C$200,$A50,'Constants & Enums'!$I$5:$I$200,B$45)+COUNTIFS('Metrics & Formulas'!$C$5:$C$200,$A50,'Metrics & Formulas'!$I$5:$I$200,B$45)+COUNTIFS('Projections & Dashboards'!$C$5:$C$200,$A50,'Projections & Dashboards'!$I$5:$I$200,B$45) | C50: =COUNTIFS('Constants & Enums'!$C$5:$C$200,$A50,'Constants & Enums'!$I$5:$I$200,C$45)+COUNTIFS('Metrics & Formulas'!$C$5:$C$200,$A50,'Metrics & Formulas'!$I$5:$I$200,C$45)+COUNTIFS('Projections & Dashboards'!$C$5:$C$200,$A50,'Projections & Dashboards'!$I$5:$I$200,C$45) | D50: =COUNTIFS('Constants & Enums'!$C$5:$C$200,$A50,'Constants & Enums'!$I$5:$I$200,D$45)+COUNTIFS('Metrics & Formulas'!$C$5:$C$200,$A50,'Metrics & Formulas'!$I$5:$I$200,D$45)+COUNTIFS('Projections & Dashboards'!$C$5:$C$200,$A50,'Projections & Dashboards'!$I$5:$I$200,D$45) | E50: =COUNTIFS('Constants & Enums'!$C$5:$C$200,$A50,'Constants & Enums'!$I$5:$I$200,E$45)+COUNTIFS('Metrics & Formulas'!$C$5:$C$200,$A50,'Metrics & Formulas'!$I$5:$I$200,E$45)+COUNTIFS('Projections & Dashboards'!$C$5:$C$200,$A50,'Projections & Dashboards'!$I$5:$I$200,E$45) | F50: =SUM(B50:E50) | G50: =IFERROR((D50+E50)/F50,0) | M50: =Listas!P9 | N50: =COUNTIF('Constants & Enums'!$D$5:$D$200,$M50) | O50: =COUNTIF('Metrics & Formulas'!$D$5:$D$200,$M50) | P50: =COUNTIF('Projections & Dashboards'!$D$5:$D$200,$M50) | Q50: =SUM(N50:P50)
A51: Dashboard | B51: =COUNTIFS('Constants & Enums'!$C$5:$C$200,$A51,'Constants & Enums'!$I$5:$I$200,B$45)+COUNTIFS('Metrics & Formulas'!$C$5:$C$200,$A51,'Metrics & Formulas'!$I$5:$I$200,B$45)+COUNTIFS('Projections & Dashboards'!$C$5:$C$200,$A51,'Projections & Dashboards'!$I$5:$I$200,B$45) | C51: =COUNTIFS('Constants & Enums'!$C$5:$C$200,$A51,'Constants & Enums'!$I$5:$I$200,C$45)+COUNTIFS('Metrics & Formulas'!$C$5:$C$200,$A51,'Metrics & Formulas'!$I$5:$I$200,C$45)+COUNTIFS('Projections & Dashboards'!$C$5:$C$200,$A51,'Projections & Dashboards'!$I$5:$I$200,C$45) | D51: =COUNTIFS('Constants & Enums'!$C$5:$C$200,$A51,'Constants & Enums'!$I$5:$I$200,D$45)+COUNTIFS('Metrics & Formulas'!$C$5:$C$200,$A51,'Metrics & Formulas'!$I$5:$I$200,D$45)+COUNTIFS('Projections & Dashboards'!$C$5:$C$200,$A51,'Projections & Dashboards'!$I$5:$I$200,D$45) | E51: =COUNTIFS('Constants & Enums'!$C$5:$C$200,$A51,'Constants & Enums'!$I$5:$I$200,E$45)+COUNTIFS('Metrics & Formulas'!$C$5:$C$200,$A51,'Metrics & Formulas'!$I$5:$I$200,E$45)+COUNTIFS('Projections & Dashboards'!$C$5:$C$200,$A51,'Projections & Dashboards'!$I$5:$I$200,E$45) | F51: =SUM(B51:E51) | G51: =IFERROR((D51+E51)/F51,0) | M51: =Listas!P10 | N51: =COUNTIF('Constants & Enums'!$D$5:$D$200,$M51) | O51: =COUNTIF('Metrics & Formulas'!$D$5:$D$200,$M51) | P51: =COUNTIF('Projections & Dashboards'!$D$5:$D$200,$M51) | Q51: =SUM(N51:P51)
A52: Total | B52: =SUM(B46:B51) | C52: =SUM(C46:C51) | D52: =SUM(D46:D51) | E52: =SUM(E46:E51) | F52: =SUM(F46:F51) | G52: =IFERROR((D52+E52)/F52,0) | M52: =Listas!P11 | N52: =COUNTIF('Constants & Enums'!$D$5:$D$200,$M52) | O52: =COUNTIF('Metrics & Formulas'!$D$5:$D$200,$M52) | P52: =COUNTIF('Projections & Dashboards'!$D$5:$D$200,$M52) | Q52: =SUM(N52:P52)
M53: =Listas!P12 | N53: =COUNTIF('Constants & Enums'!$D$5:$D$200,$M53) | O53: =COUNTIF('Metrics & Formulas'!$D$5:$D$200,$M53) | P53: =COUNTIF('Projections & Dashboards'!$D$5:$D$200,$M53) | Q53: =SUM(N53:P53)
M54: =Listas!P13 | N54: =COUNTIF('Constants & Enums'!$D$5:$D$200,$M54) | O54: =COUNTIF('Metrics & Formulas'!$D$5:$D$200,$M54) | P54: =COUNTIF('Projections & Dashboards'!$D$5:$D$200,$M54) | Q54: =SUM(N54:P54)
M55: =Listas!P14 | N55: =COUNTIF('Constants & Enums'!$D$5:$D$200,$M55) | O55: =COUNTIF('Metrics & Formulas'!$D$5:$D$200,$M55) | P55: =COUNTIF('Projections & Dashboards'!$D$5:$D$200,$M55) | Q55: =SUM(N55:P55)
M56: =Listas!P15 | N56: =COUNTIF('Constants & Enums'!$D$5:$D$200,$M56) | O56: =COUNTIF('Metrics & Formulas'!$D$5:$D$200,$M56) | P56: =COUNTIF('Projections & Dashboards'!$D$5:$D$200,$M56) | Q56: =SUM(N56:P56)
M57: =Listas!P16 | N57: =COUNTIF('Constants & Enums'!$D$5:$D$200,$M57) | O57: =COUNTIF('Metrics & Formulas'!$D$5:$D$200,$M57) | P57: =COUNTIF('Projections & Dashboards'!$D$5:$D$200,$M57) | Q57: =SUM(N57:P57)
M58: Total | N58: =SUM(N46:N57) | O58: =SUM(O46:O57) | P58: =SUM(P46:P57) | Q58: =SUM(Q46:Q57)
A76: 5 · Telas por fase legada e status (inventário original) | M76: 6 · Funções por fase legada e status (inventário original)
A77: Fase (legado) | B77: Existe | C77: Em andamento | D77: Planejada | E77: Descartada | F77: Total | M77: Fase (legado) | N77: Existe | O77: Em andamento | P77: Planejada | Q77: Descartada | R77: Total
A78: F0 | B78: =COUNTIFS(Telas!$H$5:$H$400,$A78,Telas!$J$5:$J$400,B$77) | C78: =COUNTIFS(Telas!$H$5:$H$400,$A78,Telas!$J$5:$J$400,C$77) | D78: =COUNTIFS(Telas!$H$5:$H$400,$A78,Telas!$J$5:$J$400,D$77) | E78: =COUNTIFS(Telas!$H$5:$H$400,$A78,Telas!$J$5:$J$400,E$77) | F78: =SUM(B78:E78) | M78: F0 | N78: =COUNTIFS(Funções!$F$5:$F$300,$M78,Funções!$H$5:$H$300,N$77) | O78: =COUNTIFS(Funções!$F$5:$F$300,$M78,Funções!$H$5:$H$300,O$77) | P78: =COUNTIFS(Funções!$F$5:$F$300,$M78,Funções!$H$5:$H$300,P$77) | Q78: =COUNTIFS(Funções!$F$5:$F$300,$M78,Funções!$H$5:$H$300,Q$77) | R78: =SUM(N78:Q78)
A79: F1 | B79: =COUNTIFS(Telas!$H$5:$H$400,$A79,Telas!$J$5:$J$400,B$77) | C79: =COUNTIFS(Telas!$H$5:$H$400,$A79,Telas!$J$5:$J$400,C$77) | D79: =COUNTIFS(Telas!$H$5:$H$400,$A79,Telas!$J$5:$J$400,D$77) | E79: =COUNTIFS(Telas!$H$5:$H$400,$A79,Telas!$J$5:$J$400,E$77) | F79: =SUM(B79:E79) | M79: F1 | N79: =COUNTIFS(Funções!$F$5:$F$300,$M79,Funções!$H$5:$H$300,N$77) | O79: =COUNTIFS(Funções!$F$5:$F$300,$M79,Funções!$H$5:$H$300,O$77) | P79: =COUNTIFS(Funções!$F$5:$F$300,$M79,Funções!$H$5:$H$300,P$77) | Q79: =COUNTIFS(Funções!$F$5:$F$300,$M79,Funções!$H$5:$H$300,Q$77) | R79: =SUM(N79:Q79)
A80: F2 | B80: =COUNTIFS(Telas!$H$5:$H$400,$A80,Telas!$J$5:$J$400,B$77) | C80: =COUNTIFS(Telas!$H$5:$H$400,$A80,Telas!$J$5:$J$400,C$77) | D80: =COUNTIFS(Telas!$H$5:$H$400,$A80,Telas!$J$5:$J$400,D$77) | E80: =COUNTIFS(Telas!$H$5:$H$400,$A80,Telas!$J$5:$J$400,E$77) | F80: =SUM(B80:E80) | M80: F2 | N80: =COUNTIFS(Funções!$F$5:$F$300,$M80,Funções!$H$5:$H$300,N$77) | O80: =COUNTIFS(Funções!$F$5:$F$300,$M80,Funções!$H$5:$H$300,O$77) | P80: =COUNTIFS(Funções!$F$5:$F$300,$M80,Funções!$H$5:$H$300,P$77) | Q80: =COUNTIFS(Funções!$F$5:$F$300,$M80,Funções!$H$5:$H$300,Q$77) | R80: =SUM(N80:Q80)
...

Sheet Roadmap
A1: Kodoo — roadmap revisado orientado por evidência
A2: Este plano segue as fases do repositório, não as fases legadas do catálogo de telas/funções. Estados iniciais são hipóteses da auditoria documental, não declaração de conclusão do código.
A3: Repositório | B3: https://github.com/bootstrapprx/kodoo | C3: Docs base | D3: context/roadmap.md (21/09/2026); context/domain-app-migration.md e context/application-architecture.md (19/10/2026) | M3: Atualize o Current Status somente após conferir código, testes e CI.
A5: ID | B5: Repository Phase | C5: Workstream | D5: Deliverable / Work Item | E5: Definition of Done / Acceptance Criteria | F5: Priority | G5: Initial Status | H5: Dependencies | I5: Required Evidence | J5: Source / Notes | K5: Owner | L5: Target | M5: Current Status | N5: Evidence Link / Path / Command
A6: RM-001 | B6: F0 | C6: Governança do roadmap | D6: Confirmar decisões de execução/provisionamento e registrar as decisões abertas. | E6: Cada decisão tem valor escolhido, justificativa, responsável e consequência técnica; docs/scripts refletem a decisão. | F6: P0 | G6: A validar | H6: — | I6: Registro de decisões + execução em ambiente limpo | J6: context/roadmap.md | M6: A validar
A7: RM-002 | B7: F1 | C7: Banco e migrações | D7: Validar bootstrap de papéis PostgreSQL, ownership, migrations e checks SQL em ambiente limpo. | E7: Pipeline reproduzível desde banco vazio; papéis e ownership corretos; falhas de migration/check impedem avanço. | F7: P0 | G7: Parcial/documentado; validar HEAD | H7: RM-001 | I7: Log CI + execução local documentada | J7: context/roadmap.md; .github/workflows/ci.yml | M7: A validar
A8: RM-003 | B8: F2 | C8: Identidade e escopo | D8: Fechar contrato de ator, organização ativa e propagação de contexto em todas as entradas relevantes. | E8: Contexto ausente/malformado é rejeitado; autorização aplicada no servidor, não apenas na UI; sem vazamento entre organizações. | F8: P0 | G8: Implementado no primeiro slice; aceite CI pendente | H8: RM-002 | I8: Testes de contexto Rust + SQL F2; API auth remains F3 | J8: context/roadmap.md; context/identity-isolation.md; context/f2-authorization-matrix.md | M8: Em andamento | N8: crates/kodoo-core; crates/kodoo-postgres/tests/identity_context.rs; tests/database/0005-f2-isolation.sql
A9: RM-004 | B9: F2 | C9: Autorização e isolamento | D9: Criar matriz de permissões por ação e validar acesso cruzado entre organizações. | E9: Ações permitidas/negadas documentadas; testes provam negação por padrão e isolamento de dados em sucesso, erro e rollback. | F9: P0 | G9: Implementado no primeiro slice; aceite CI pendente | H9: RM-003 | I9: Matriz por operação + negação por padrão + isolamento cross-org | J9: context/f2-authorization-matrix.md; schema/postgresql/migrations/0041-restrictive-worker-rls.sql | M9: Em andamento | N9: schema/postgresql/checks/0002-f2-worker-scope.sql; tests/database/0005-f2-isolation.sql
A10: RM-005 | B10: F3 | C10: Fatia vertical nativa | D10: Escolher uma operação de negócio estreita e concluí-la ponta a ponta com persistência durável. | E10: API, domínio/use case, PostgreSQL, autorização, auditoria, CLI e testes representam a mesma regra; sem estado em memória como fonte de verdade. | F10: P0 | G10: Implementado na fatia Project Manager; aceite CI pendente | H10: RM-003; RM-004 | I10: Teste SQL F3 + API/caso de uso + CLI/MCP; workspace CI pendente | J10: context/f3-project-manager.md; tests/database/0006-f3-project-manager.sql | M10: Em andamento | N10: modules/project-manager; crates/kodoo-postgres/src/project_manager.rs; backend/src/api.rs
A11: RM-006 | B11: F3 | C11: Auditoria e transições | D11: Formalizar eventos auditáveis e transições inválidas da primeira fatia. | E11: Cada mutação relevante deixa evidência; transições inválidas e chamadas não autorizadas falham com erro estável e teste. | F11: P1 | G11: Auditoria e transições implementadas; aceite CI pendente | H11: RM-005 | I11: Migração 0042 + teste de transição inválida e auditoria same-transaction | J11: schema/postgresql/migrations/0042-project-manager-audit.sql; tests/database/0006-f3-project-manager.sql | M11: Em andamento | N11: audit.event; administration.record_event; project_manager.transition_task
A12: RM-007 | B12: F4 | C12: Outbox e worker | D12: Fechar ciclo de vida de efeitos externos: agendamento, retry, deduplicação e recuperação. | E12: Falhas temporárias, timeout ambíguo e entregas duplicadas são testados; estado final e reprocessamento são determinísticos. | F12: P1 | G12: Infra parcial/documentada | H12: RM-005 | I12: Testes de falha/duplicação/retomada em stack real | J12: context/roadmap.md | M12: A validar
A13: RM-008 | B13: F4 | C13: Integrações concretas | D13: Listar providers reais e implementar dispatchers faltantes sem espalhar regra de domínio. | E13: Cada provider tem contrato, configuração segura, timeout, retry, idempotência e testes de contrato. | F13: P2 | G13: Pendente/documentado | H13: RM-007 | I13: Testes de contrato e configuração de exemplo sem segredos | J13: context/roadmap.md | M13: A validar
A14: RM-009 | B14: F5 | C14: Inventário de origem | D14: Inventariar dados, fluxos e dependências do sistema de origem antes de desenhar importação. | E14: Inventário versionado; cada entidade tem volume, proprietário, mapeamento, qualidade e regra de reconciliação. | F14: P1 | G14: Pendente/documentado | H14: RM-005 | I14: Relatório de inventário revisável | J14: context/roadmap.md | M14: A validar
A15: RM-010 | B15: F5 | C15: Ensaio de importação | D15: Construir ensaio repetível e determinístico com proveniência e reconciliação. | E15: Importar duas vezes produz resultado controlado; divergências são explicadas; proveniência por registro; plano de correção/rollback documentado. | F15: P1 | G15: Pendente/documentado | H15: RM-009 | I15: Relatório de dry-run + fixtures representativas | J15: context/roadmap.md | M15: A validar
A16: RM-011 | B16: F5 | C16: Adaptador Odoo restrito | D16: Definir e testar o contrato mínimo de compatibilidade necessário para migração. | E16: Adaptador limitado a contratos explícitos; sem replicar arquitetura do legado; testes de contrato e limites de uso. | F16: P2 | G16: Pendente/documentado | H16: RM-009; RM-010 | I16: Contrato versionado + testes de contrato | J16: README.md; context/roadmap.md | M16: A validar
A17: RM-012 | B17: F6 | C17: Cutover e fencing | D17: Desenhar e ensaiar corte controlado com bloqueio de escrita no sistema antigo. | E17: Fencing demonstrado; nenhuma escrita concorrente obsoleta; reconciliação antes/depois; recuperação testada sem perder escrita aceita. | F17: P1 | G17: Pendente/documentado | H17: RM-010; RM-011 | I17: Ensaio completo com relatório de reconciliação | J17: context/roadmap.md | M17: A validar
A18: RM-013 | B18: A1 | C18: Autoridade do ledger | D18: Verificar que TigerBeetle é autoridade contábil e só é acessado pelo módulo de contabilidade. | E18: Limite arquitetural respeitado; nenhum acesso a TigerBeetle por kodoo-core/outros módulos; testes/CI protegem a regra. | F18: P0 | G18: Regra arquitetural documentada; validar código atual | H18: RM-002 | I18: Busca de dependências + teste/checagem estrutural | J18: README.md; context/application-architecture.md | M18: A validar
A19: RM-014 | B19: A1 | C19: Postagem e reversão | D19: Fechar ciclos de períodos, lançamentos, lotes, estornos e fechamento ainda com TODOs. | E19: Invariantes de partidas dobradas; idempotência e correções sem apagar histórico; casos de período fechado cobertos. | F19: P0 | G19: Parcial; há lacunas/TODOs documentados | H19: RM-003; RM-013 | I19: Testes de domínio e integração com TigerBeetle real | J19: context/domain-app-migration.md | M19: A validar
A20: RM-015 | B20: A1 | C20: Reconciliação bancária e subledger | D20: Definir modelo de reconciliação entre extratos, subledger, diário e ledger autoritativo. | E20: Diferenças explicáveis; não há ajuste silencioso; histórico de conciliação e exceções é auditável. | F20: P1 | G20: Lacuna identificada na auditoria documental | H20: RM-014 | I20: Casos de aceitação com divergência e correção | J20: context/domain-app-migration.md | M20: A validar
A21: RM-016 | B21: A1 | C21: Relatórios contábeis e trilha | D21: Validar razão, balancete e demonstrações contra a fonte contábil autoritativa. | E21: Relatórios reconciliam com o ledger; filtros/intervalos definidos; trilha de auditoria permite explicar cada saldo. | F21: P1 | G21: Parcial; validar read models restantes | H21: RM-014 | I21: Testes de reconciliação e fixtures de aceitação | J21: context/domain-app-migration.md | M21: A validar
A22: RM-017 | B22: A1 | C22: Read models do Kalkulisto | D22: Completar os read models que faltam e integrá-los à aplicação de domínio. | E22: Estados de carregamento/vazio/erro; autorização; paginação/filtros quando aplicáveis; nenhum dado fictício em produção. | F22: P1 | G22: Parcial; lacunas documentadas | H22: RM-003; RM-014; RM-016 | I22: Teste UI/integração e verificação desktop real | J22: context/domain-app-migration.md; context/application-architecture.md | M22: A validar
A23: RM-018 | B23: A1 | C23: QA com stack real | D23: Definir evidência de aceitação para cada fatia contábil em Docker/stack real. | E23: Testes passam com PostgreSQL e TigerBeetle reais; falhas de rede/duplicação/recuperação relevantes cobertas; comandos reproduzíveis. | F23: P0 | G23: Necessário por fatia | H23: RM-014; RM-015; RM-016 | I23: Relatório QA por fatia + CI | J23: context/domain-app-migration.md; .github/workflows/ci.yml | M23: A validar
... A31: RM-026 | B31: Transversal | C31: Dependências e proprietários das definições | D31: Mapear relações entre métricas, funções, tabelas, módulos e telas na aba Dependencies e resolver proprietários pendentes. | E31: Toda definição tem proprietário explícito (ou decisão pendente registrada); nenhuma dependência aponta para ID inexistente; localização não é inventada. | F31: P2 | G31: A validar | H31: RM-023; RM-024; RM-025 | I31: Aba Dependencies sem alertas + decisões registradas | J31: Resposta sobre projeções (aba Racional (Constantes)) | M31: A validar

Sheet Telas
A1: Telas: o que preciso ter, em que fase e em que estado
A2: Edite as colunas com lista suspensa e os textos. A coluna Família (cinza) é fórmula. Adicione telas nas linhas livres abaixo, usando o próximo ID sugerido na aba Leia-me. Use o filtro do cabeçalho para navegar.
O3: Fase do roadmap do repositório; preencher após validar item a item. | P3: Caminho, teste, PR ou comando que prova o estado real.
A4: ID | B4: Módulo | C4: Tela | D4: Arquétipo | E4: Família | F4: Entidade | G4: Descrição | H4: Fase catálogo antigo (não equivalente às fases do repo) | I4: Prioridade | J4: Status do inventário (não verificado no código) | K4: Funções (IDs) | L4: Depende de (IDs) | M4: Spec (ViewSpec) | N4: Notas | O4: Fase Kodoo (reclassificar) | P4: Evidência no repositório
A5: T-001 | B5: Shell e Navegação | C5: Login | D5: Shell | E5: =IF(D5="","",IFERROR(INDEX(Arquétipos!$B$5:$B$40,MATCH(D5,Arquétipos!$A$5:$A$40,0)),"")) | G5: Autenticação do usuário | H5: F0 | I5: Alta | J5: Planejada | K5: FN-013 | M5: Não
A6: T-002 | B6: Shell e Navegação | C6: Lançador de módulos | D6: Launcher | E6: =IF(D6="","",IFERROR(INDEX(Arquétipos!$B$5:$B$40,MATCH(D6,Arquétipos!$A$5:$A$40,0)),"")) | G6: Ponto de entrada; esconde módulos sem permissão | H6: F0 | I6: Alta | J6: Planejada | K6: FN-014 | L6: T-001 | M6: Não
A7: T-003 | B7: Shell e Navegação | C7: Navegação lateral e breadcrumbs | D7: Shell | E7: =IF(D7="","",IFERROR(INDEX(Arquétipos!$B$5:$B$40,MATCH(D7,Arquétipos!$A$5:$A$40,0)),"")) | H7: F0 | I7: Alta | J7: Planejada | M7: Não
A8: T-004 | B8: Shell e Navegação | C8: Estados padrão (carregando, vazio, erro) | D8: Shell | E8: =IF(D8="","",IFERROR(INDEX(Arquétipos!$B$5:$B$40,MATCH(D8,Arquétipos!$A$5:$A$40,0)),"")) | G8: Componentes de ViewState usados por todos os arquétipos | H8: F0 | I8: Alta | J8: Planejada | M8: Não
A9: T-005 | B9: Shell e Navegação | C9: Acesso negado | D9: Shell | E9: =IF(D9="","",IFERROR(INDEX(Arquétipos!$B$5:$B$40,MATCH(D9,Arquétipos!$A$5:$A$40,0)),"")) | H9: F0 | I9: Média | J9: Planejada | K9: FN-014 | M9: Não
A10: T-006 | B10: Shell e Navegação | C10: Página não encontrada (404) | D10: Shell | E10: =IF(D10="","",IFERROR(INDEX(Arquétipos!$B$5:$B$40,MATCH(D10,Arquétipos!$A$5:$A$40,0)),"")) | H10: F0 | I10: Baixa | J10: Planejada | M10: Não
A11: T-007 | B11: Shell e Navegação | C11: Seleção de organização | D11: Shell | E11: =IF(D11="","",IFERROR(INDEX(Arquétipos!$B$5:$B$40,MATCH(D11,Arquétipos!$A$5:$A$40,0)),"")) | G11: Escolher a organização ativa | H11: F2 | I11: Alta | J11: Planejada | K11: FN-020 | L11: T-001 | M11: Não
A12: T-008 | B12: Shell e Navegação | C12: Perfil do usuário | D12: Form | E12: =IF(D12="","",IFERROR(INDEX(Arquétipos!$B$5:$B$40,MATCH(D12,Arquétipos!$A$5:$A$40,0)),"")) | H12: F2 | I12: Baixa | J12: Planejada | M12: Não
A13: T-009 | B13: Shell e Navegação | C13: Preferências de interface (tema, idioma, densidade) | D13: Settings | E13: =IF(D13="","",IFERROR(INDEX(Arquétipos!$B$5:$B$40,MATCH(D13,Arquétipos!$A$5:$A$40,0)),"")) | H13: F2 | I13: Baixa | J13: Planejada | K13: FN-010 | M13: Não
A14: T-010 | B14: Shell e Navegação | C14: Busca global | D14: List | E14: =IF(D14="","",IFERROR(INDEX(Arquétipos!$B$5:$B$40,MATCH(D14,Arquétipos!$A$5:$A$40,0)),"")) | H14: F4 | I14: Média | J14: Planejada | M14: Não
A15: T-011 | B15: Shell e Navegação | C15: Centro de notificações | D15: List | E15: =IF(D15="","",IFERROR(INDEX(Arquétipos!$B$5:$B$40,MATCH(D15,Arquétipos!$A$5:$A$40,0)),"")) | H15: F4 | I15: Baixa | J15: Planejada | M15: Não
A16: T-012 | B16: Shell e Navegação | C16: Paleta de comandos e atalhos | D16: Shell | E16: =IF(D16="","",IFERROR(INDEX(Arquétipos!$B$5:$B$40,MATCH(D16,Arquétipos!$A$5:$A$40,0)),"")) | H16: F5 | I16: Baixa | J16: Planejada | M16: Não
A17: T-013 | B17: Shell e Navegação | C17: Recuperação de senha | D17: Shell | E17: =IF(D17="","",IFERROR(INDEX(Arquétipos!$B$5:$B$40,MATCH(D17,Arquétipos!$A$5:$A$40,0)),"")) | H17: F5 | I17: Média | J17: Planejada | K17: FN-017 | M17: Não
A18: T-014 | B18: Fundação e Infraestrutura | C18: Galeria de arquétipos (com fixtures) | D18: List | E18: =IF(D18="","",IFERROR(INDEX(Arquétipos!$B$5:$B$40,MATCH(D18,Arquétipos!$A$5:$A$40,0)),"")) | G18: Mostra cada arquétipo com dados de teste; ferramenta de visualização e aprendizado | H18: F0 | I18: Alta | J18: Planejada | K18: FN-002, FN-003 | L18: T-003 | M18: Não
A19: T-015 | B19: Fundação e Infraestrutura | C19: Inspetor de ViewSpec | D19: Detail | E19: =IF(D19="","",IFERROR(INDEX(Arquétipos!$B$5:$B$40,MATCH(D19,Arquétipos!$A$5:$A$40,0)),"")) | G19: Exibe a spec de cada tela e os erros de validação | H19: F0 | I19: Média | J19: Planejada | K19: FN-001 | L19: T-014 | M19: Não
A20: T-016 | B20: Fundação e Infraestrutura | C20: Painel de verificação de funções (Ratatui) | D20: Shell | E20: =IF(D20="","",IFERROR(INDEX(Arquétipos!$B$5:$B$40,MATCH(D20,Arquétipos!$A$5:$A$40,0)),"")) | G20: Verifica funções de domínio sem passar pela UI | H20: F1 | I20: Média | J20: Planejada | K20: FN-008, FN-007 | M20: Não
A21: T-017 | B21: Administração e Segurança | C21: Organizações | D21: List | E21: =IF(D21="","",IFERROR(INDEX(Arquétipos!$B$5:$B$40,MATCH(D21,Arquétipos!$A$5:$A$40,0)),"")) | H21: F2 | I21: Alta | J21: Planejada | K21: FN-020 | L21: T-002 | M21: Não
A22: T-018 | B22: Administração e Segurança | C22: Organização | D22: Form | E22: =IF(D22="","",IFERROR(INDEX(Arquétipos!$B$5:$B$40,MATCH(D22,Arquétipos!$A$5:$A$40,0)),"")) | H22: F2 | I22: Alta | J22: Planejada | K22: FN-020 | M22: Não
A23: T-019 | B23: Administração e Segurança | C23: Parâmetros gerais | D23: Settings | E23: =IF(D23="","",IFERROR(INDEX(Arquétipos!$B$5:$B$40,MATCH(D23,Arquétipos!$A$5:$A$40,0)),"")) | H23: F2 | I23: Média | J23: Planejada | K23: FN-021 | M23: Não
A24: T-020 | B24: Administração e Segurança | C24: Sequências de numeração | D24: Settings | E24: =IF(D24="","",IFERROR(INDEX(Arquétipos!$B$5:$B$40,MATCH(D24,Arquétipos!$A$5:$A$40,0)),"")) | H24: F2 | I24: Média | J24: Planejada | K24: FN-022, FN-037 | M24: Não
A25: T-021 | B25: Administração e Segurança | C25: Usuários | D25: List | E25: =IF(D25="","",IFERROR(INDEX(Arquétipos!$B$5:$B$40,MATCH(D25,Arquétipos!$A$5:$A$40,0)),"")) | H25: F5 | I25: Média | J25: Planejada | K25: FN-018 | M25: Não
A26: T-022 | B26: Administração e Segurança | C26: Usuário | D26: Form | E26: =IF(D26="","",IFERROR(INDEX(Arquétipos!$B$5:$B$40,MATCH(D26,Arquétipos!$A$5:$A$40,0)),"")) | H26: F5 | I26: Média | J26: Planejada | K26: FN-018 | M26: Não
A27: T-023 | B27: Administração e Segurança | C27: Papéis | D27: List | E27: =IF(D27="","",IFERROR(INDEX(Arquétipos!$B$5:$B$40,MATCH(D27,Arquétipos!$A$5:$A$40,0)),"")) | H27: F5 | I27: Média | J27: Planejada | K27: FN-019 | M27: Não
A28: T-024 | B28: Administração e Segurança | C28: Papel e permissões | D28: MasterDetail | E28: =IF(D28="","",IFERROR(INDEX(Arquétipos!$B$5:$B$40,MATCH(D28,Arquétipos!$A$5:$A$40,0)),"")) | H28: F5 | I28: Média | J28: Planejada | K28: FN-019 | M28: Não
A29: T-025 | B29: Administração e Segurança | C29: Matriz papel × permissão | D29: Mapping | E29: =IF(D29="","",IFERROR(INDEX(Arquétipos!$B$5:$B$40,MATCH(D29,Arquétipos!$A$5:$A$40,0)),"")) | H29: F5 | I29: Média | J29: Planejada | K29: FN-019 | M29: Não
A30: T-026 | B30: Administração e Segurança | C30: Sessões ativas | D30: List | E30: =IF(D30="","",IFERROR(INDEX(Arquétipos!$B$5:$B$40,MATCH(D30,Arquétipos!$A$5:$A$40,0)),"")) | H30: F5 | I30: Baixa | J30: Planejada | K30: FN-015 | M30: Não
A31: T-027 | B31: Administração e Segurança | C31: Autenticação em dois fatores | D31: Settings | E31: =IF(D31="","",IFERROR(INDEX(Arquétipos!$B$5:$B$40,MATCH(D31,Arquétipos!$A$5:$A$40,0)),"")) | H31: F5 | I31: Média | J31: Planejada | K31: FN-016 | M31: Não
A32: T-028 | B32: Administração e Segurança | C32: Log de acessos | D32: AuditTrail | E32: =IF(D32="","",IFERROR(INDEX(Arquétipos!$B$5:$B$40,MATCH(D32,Arquétipos!$A$5:$A$40,0)),"")) | H32: F5 | I32: Baixa | J32: Planejada | K32: FN-113 | M32: Não
A33: T-029 | B33: Administração e Segurança | C33: Integrações e chaves de API | D33: Settings | E33: =IF(D33="","",IFERROR(INDEX(Arquétipos!$B$5:$B$40,MATCH(D33,Arquétipos!$A$5:$A$40,0)),"")) | H33: F6 | I33: Baixa | J33: Planejada | K33: FN-111 | M33: Não
A34: T-030 | B34: Administração e Segurança | C34: Backup e restauração | D34: Wizard | E34: =IF(D34="","",IFERROR(INDEX(Arquétipos!$B$5:$B$40,MATCH(D34,Arquétipos!$A$5:$A$40,0)),"")) | H34: F6 | I34: Média | J34: Planejada | K34: FN-012 | M34: Não
A35: T-031 | B35: Plano de Contas | C35: Plano de contas | D35: Tree | E35: =IF(D35="","",IFERROR(INDEX(Arquétipos!$B$5:$B$40,MATCH(D35,Arquétipos!$A$5:$A$40,0)),"")) | F35: conta | G35: Hierarquia de contas; primeira fatia vertical | H35: F1 | I35: Alta | J35: Planejada | K35: FN-026, FN-029 | L35: T-003 | M35: Não
A36: T-032 | B36: Plano de Contas | C36: Conta | D36: Form | E36: =IF(D36="","",IFERROR(INDEX(Arquétipos!$B$5:$B$40,MATCH(D36,Arquétipos!$A$5:$A$40,0)),"")) | F36: conta | H36: F1 | I36: Alta | J36: Planejada | K36: FN-027, FN-028, FN-024, FN-023, FN-025 | L36: T-031 | M36: Não
A37: T-033 | B37: Plano de Contas | C37: Detalhe da conta (saldo e movimento) | D37: Detail | E37: =IF(D37="","",IFERROR(INDEX(Arquétipos!$B$5:$B$40,MATCH(D37,Arquétipos!$A$5:$A$40,0)),"")) | F37: conta | H37: F1 | I37: Média | J37: Planejada | K37: FN-051, FN-052 | L37: T-031 | M37: Não
A38: T-034 | B38: Plano de Contas | C38: Naturezas e tipos de conta | D38: List | E38: =IF(D38="","",IFERROR(INDEX(Arquétipos!$B$5:$B$40,MATCH(D38,Arquétipos!$A$5:$A$40,0)),"")) | H38: F1 | I38: Média | J38: Planejada | M38: Não
A39: T-035 | B39: Plano de Contas | C39: Importar plano de contas | D39: Import | E39: =IF(D39="","",IFERROR(INDEX(Arquétipos!$B$5:$B$40,MATCH(D39,Arquétipos!$A$5:$A$40,0)),"")) | H39: F2 | I39: Média | J39: Planejada | K39: FN-031, FN-109 | L39: T-031 | M39: Não
A40: T-036 | B40: Plano de Contas | C40: Mapeamento para plano referencial | D40: Mapping | E40: =IF(D40="","",IFERROR(INDEX(Arquétipos!$B$5:$B$40,MATCH(D40,Arquétipos!$A$5:$A$40,0)),"")) | H40: F3 | I40: Média | J40: Planejada | K40: FN-032 | L40: T-031 | M40: Não
...

Sheet Funções
A1: Function inventory — repository mapping and English identifiers
A2: English identifiers are proposed translations of legacy catalog names, not Rust symbol names. Parent-module mappings are hypotheses until checked against code.
M3: Repository roadmap phase; classify after checking each function. | N3: Code path, test, PR, or command proving actual implementation. | O3: Proposed English identifier; not necessarily an existing symbol. | P3: Parent module/crate that should own the capability. | Q3: Submodule or capability area. | R3: Repository entry point. Confirm exact file/symbol. | S3: Confidence / follow-up required.
A4: Function ID | B4: Legacy Module Label | C4: Legacy Function / Command | D4: Function Type | E4: Description (Portuguese source) | F4: Legacy Phase (not repository phase) | G4: Priority | H4: Inventory Status (unverified) | I4: Screens Using (IDs) | J4: CLI / Ratatui Verified | K4: Tests | L4: Notes | M4: Repository Phase (reclassify) | N4: Repository Evidence | O4: Function / Command (English) | P4: Parent Module | Q4: Submodule / Capability | R4: Repository Link | S4: Mapping Confidence
A5: FN-001 | B5: Fundação e Infraestrutura | C5: kodoo_view.validar_spec | D5: Infra | E5: Validação estrutural de ViewSpec (esqueleto gerado, não compilado) | F5: F0 | G5: Alta | H5: Em andamento | I5: T-015 | J5: Não | K5: Não | O5: kodoo_view.validate_spec | P5: kodoo-core | Q5: foundation / infrastructure | R5: https://github.com/bootstrapprx/kodoo/tree/main/crates/kodoo-core | S5: Conceptual mapping; confirm exact crate
A6: FN-002 | B6: Fundação e Infraestrutura | C6: ui.renderizar_arquetipo | D6: Infra | E6: Renderizador genérico por arquétipo (Dioxus) | F6: F0 | G6: Alta | H6: Planejada | I6: T-014 | J6: Não | K6: Não | O6: ui.renderizar_arquetipo | P6: kodoo-core | Q6: foundation / infrastructure | R6: https://github.com/bootstrapprx/kodoo/tree/main/crates/kodoo-core | S6: Conceptual mapping; confirm exact crate
A7: FN-003 | B7: Fundação e Infraestrutura | C7: dev.fixtures_carregar | D7: Infra | E7: Dados de teste tipados para as telas | F7: F0 | G7: Alta | H7: Planejada | I7: T-014 | J7: Não | K7: Não | O7: dev.fixtures_carregar | P7: kodoo-core | Q7: foundation / infrastructure | R7: https://github.com/bootstrapprx/kodoo/tree/main/crates/kodoo-core | S7: Conceptual mapping; confirm exact crate
A8: FN-004 | B8: Fundação e Infraestrutura | C8: dominio.repositorio | D8: Infra | E8: Interface de repositório extraída do que as telas pedem | F8: F1 | G8: Alta | H8: Planejada | J8: Não | K8: Não | O8: dominio.repository | P8: kodoo-core | Q8: foundation / infrastructure | R8: https://github.com/bootstrapprx/kodoo/tree/main/crates/kodoo-core | S8: Conceptual mapping; confirm exact crate
A9: FN-005 | B9: Fundação e Infraestrutura | C9: db.migrar_esquema | D9: Infra | E9: Migrações do PostgreSQL | F9: F1 | G9: Alta | H9: Planejada | J9: Não | K9: Não | O9: db.migrar_esquema | P9: kodoo-core | Q9: foundation / infrastructure | R9: https://github.com/bootstrapprx/kodoo/tree/main/crates/kodoo-core | S9: Conceptual mapping; confirm exact crate
A10: FN-006 | B10: Fundação e Infraestrutura | C10: api.servidor_base | D10: Infra | E10: API: rotas, erros e versionamento | F10: F1 | G10: Alta | H10: Planejada | J10: Não | K10: Não | O10: api.servidor_base | P10: kodoo-core | Q10: foundation / infrastructure | R10: https://github.com/bootstrapprx/kodoo/tree/main/crates/kodoo-core | S10: Conceptual mapping; confirm exact crate
A11: FN-007 | B11: Fundação e Infraestrutura | C11: cli.comando_base | D11: Infra | E11: CLI com os mesmos nomes de comando do domínio | F11: F1 | G11: Alta | H11: Planejada | I11: T-016 | J11: Não | K11: Não | O11: cli.comando_base | P11: kodoo-core | Q11: foundation / infrastructure | R11: https://github.com/bootstrapprx/kodoo/tree/main/crates/kodoo-core | S11: Conceptual mapping; confirm exact crate
A12: FN-008 | B12: Fundação e Infraestrutura | C12: tui.verificador | D12: Infra | E12: Ratatui para verificação direta de funções | F12: F1 | G12: Média | H12: Planejada | I12: T-016 | J12: Não | K12: Não | O12: tui.verifier | P12: kodoo-core | Q12: foundation / infrastructure | R12: https://github.com/bootstrapprx/kodoo/tree/main/crates/kodoo-core | S12: Conceptual mapping; confirm exact crate
A13: FN-009 | B13: Fundação e Infraestrutura | C13: db.seed_demo | D13: Infra | E13: Dados de demonstração no banco | F13: F1 | G13: Média | H13: Planejada | J13: Não | K13: Não | O13: db.seed_demo | P13: kodoo-core | Q13: foundation / infrastructure | R13: https://github.com/bootstrapprx/kodoo/tree/main/crates/kodoo-core | S13: Conceptual mapping; confirm exact crate
A14: FN-010 | B14: Fundação e Infraestrutura | C14: ui.i18n_carregar | D14: Infra | E14: Carregar traduções (pt-BR e en) | F14: F2 | G14: Média | H14: Planejada | I14: T-009 | J14: Não | K14: Não | O14: ui.i18n_carregar | P14: kodoo-core | Q14: foundation / infrastructure | R14: https://github.com/bootstrapprx/kodoo/tree/main/crates/kodoo-core | S14: Conceptual mapping; confirm exact crate
A15: FN-011 | B15: Fundação e Infraestrutura | C15: infra.provisionar_organizacao | D15: Infra | E15: Provisionar organização (multi-tenant) | F15: F6 | G15: Baixa | H15: Planejada | J15: Não | K15: Não | O15: infra.provisionar_organization | P15: kodoo-core | Q15: foundation / infrastructure | R15: https://github.com/bootstrapprx/kodoo/tree/main/crates/kodoo-core | S15: Conceptual mapping; confirm exact crate
A16: FN-012 | B16: Fundação e Infraestrutura | C16: infra.backup_restaurar | D16: Infra | E16: Backup e restauração | F16: F6 | G16: Média | H16: Planejada | I16: T-030 | J16: Não | K16: Não | O16: infra.backup_restaurar | P16: kodoo-core | Q16: foundation / infrastructure | R16: https://github.com/bootstrapprx/kodoo/tree/main/crates/kodoo-core | S16: Conceptual mapping; confirm exact crate
A17: FN-013 | B17: Administração e Segurança | C17: auth.autenticar | D17: Segurança | E17: Login e emissão de sessão | F17: F0 | G17: Alta | H17: Planejada | I17: T-001 | J17: Não | K17: Não | O17: auth.authenticate | P17: kodoo-core | Q17: identity / authorization (verify ownership) | R17: https://github.com/bootstrapprx/kodoo/tree/main/crates/kodoo-core | S17: Conceptual mapping; confirm exact crate
A18: FN-014 | B18: Administração e Segurança | C18: auth.autorizar | D18: Segurança | E18: Checagem de permissão por tela e ação | F18: F1 | G18: Alta | H18: Planejada | I18: T-002, T-005 | J18: Não | K18: Não | O18: auth.authorize | P18: kodoo-core | Q18: identity / authorization (verify ownership) | R18: https://github.com/bootstrapprx/kodoo/tree/main/crates/kodoo-core | S18: Conceptual mapping; confirm exact crate
A19: FN-015 | B19: Administração e Segurança | C19: auth.renovar_sessao | D19: Segurança | E19: Renovar e encerrar sessão | F19: F2 | G19: Média | H19: Planejada | I19: T-026 | J19: Não | K19: Não | O19: auth.renovar_session | P19: kodoo-core | Q19: identity / authorization (verify ownership) | R19: https://github.com/bootstrapprx/kodoo/tree/main/crates/kodoo-core | S19: Conceptual mapping; confirm exact crate
A20: FN-016 | B20: Administração e Segurança | C20: auth.mfa | D20: Segurança | E20: Segundo fator de autenticação | F20: F5 | G20: Média | H20: Planejada | I20: T-027 | J20: Não | K20: Não | O20: auth.mfa | P20: kodoo-core | Q20: identity / authorization (verify ownership) | R20: https://github.com/bootstrapprx/kodoo/tree/main/crates/kodoo-core | S20: Conceptual mapping; confirm exact crate
A21: FN-017 | B21: Administração e Segurança | C21: auth.recuperar_senha | D21: Segurança | E21: Recuperação de senha | F21: F5 | G21: Média | H21: Planejada | I21: T-013 | J21: Não | K21: Não | O21: auth.recuperar_senha | P21: kodoo-core | Q21: identity / authorization (verify ownership) | R21: https://github.com/bootstrapprx/kodoo/tree/main/crates/kodoo-core | S21: Conceptual mapping; confirm exact crate
A22: FN-018 | B22: Administração e Segurança | C22: admin.usuario.gerir | D22: Comando | E22: Criar, editar e desativar usuário | F22: F5 | G22: Média | H22: Planejada | I22: T-021, T-022 | J22: Não | K22: Não | O22: admin.user.manage | P22: kodoo-core | Q22: identity / authorization (verify ownership) | R22: https://github.com/bootstrapprx/kodoo/tree/main/crates/kodoo-core | S22: Conceptual mapping; confirm exact crate
A23: FN-019 | B23: Administração e Segurança | C23: admin.papel.gerir | D23: Comando | E23: Papéis e permissões | F23: F5 | G23: Média | H23: Planejada | I23: T-023, T-024, T-025 | J23: Não | K23: Não | O23: admin.role.manage | P23: kodoo-core | Q23: identity / authorization (verify ownership) | R23: https://github.com/bootstrapprx/kodoo/tree/main/crates/kodoo-core | S23: Conceptual mapping; confirm exact crate
A24: FN-020 | B24: Administração e Segurança | C24: admin.organizacao.gerir | D24: Comando | E24: Organização ou empresa | F24: F2 | G24: Alta | H24: Planejada | I24: T-007, T-017, T-018 | J24: Não | K24: Não | O24: admin.organization.manage | P24: kodoo-core | Q24: identity / authorization (verify ownership) | R24: https://github.com/bootstrapprx/kodoo/tree/main/crates/kodoo-core | S24: Conceptual mapping; confirm exact crate
A25: FN-021 | B25: Administração e Segurança | C25: admin.parametros.salvar | D25: Comando | E25: Parâmetros gerais | F25: F2 | G25: Média | H25: Planejada | I25: T-019 | J25: Não | K25: Não | O25: admin.settings.save | P25: kodoo-core | Q25: identity / authorization (verify ownership) | R25: https://github.com/bootstrapprx/kodoo/tree/main/crates/kodoo-core | S25: Conceptual mapping; confirm exact crate
A26: FN-022 | B26: Administração e Segurança | C26: admin.sequencia.proximo | D26: Comando | E26: Numeração sequencial | F26: F2 | G26: Média | H26: Planejada | I26: T-020 | J26: Não | K26: Não | O26: admin.sequencia.next | P26: kodoo-core | Q26: identity / authorization (verify ownership) | R26: https://github.com/bootstrapprx/kodoo/tree/main/crates/kodoo-core | S26: Conceptual mapping; confirm exact crate
A27: FN-023 | B27: Plano de Contas | C27: contabil.invariante.hierarquia_sem_ciclos | D27: Invariante | E27: Plano de contas sem ciclos | F27: F1 | G27: Alta | H27: Planejada | I27: T-032 | J27: Não | K27: Não | O27: contabil.invariant.hierarquia_sem_ciclos | P27: accounting | Q27: chart | R27: https://github.com/bootstrapprx/kodoo/tree/main/modules/accounting | S27: Likely mapping; confirm exact function
... A39: FN-035 | B39: Lançamentos e Diários | C39: contabil.invariante.imutavel_postado | D39: Invariante | E39: Lançamento postado não é alterado | F39: F1 | G39: Alta | H39: Planejada | I39: T-044 | J39: Não | K39: Não | O39: contabil.invariant.imutavel_postado | P39: accounting | Q39: core / journal | R39: https://github.com/bootstrapprx/kodoo/tree/main/modules/accounting | S39: Likely mapping; confirm exact function
A40: FN-036 | B40: Lançamentos e Diários | C40: contabil.invariante.moeda_consistente | D40: Invariante | E40: Consistência de moeda nas partidas | F40: F2 | G40: Média | H40: Planejada | J40: Não | K40: Não | O40: contabil.invariant.currency_consistente | P40: accounting | Q40: core / journal | R40: https://github.com/bootstrapprx/kodoo/tree/main/modules/accounting | S40: Likely mapping; confirm exact function
A41: FN-037 | B41: Lançamentos e Diários | C41: contabil.invariante.numeracao_sem_lacunas | D41: Invariante | E41: Numeração sem lacunas | F41: F2 | G41: Média | H41: Planejada | I41: T-020 | J41: Não | K41: Não | O41: contabil.invariant.numeracao_sem_lacunas | P41: accounting | Q41: core / journal | R41: https://github.com/bootstrapprx/kodoo/tree/main/modules/accounting | S41: Likely mapping; confirm exact function
A42: FN-038 | B42: Lançamentos e Diários | C42: contabil.diario.gerir | D42: Comando | E42: Criar e editar diário | F42: F1 | G42: Alta | H42: Planejada | I42: T-041, T-042 | J42: Não | K42: Não | O42: contabil.journal.manage | P42: accounting | Q42: core / journal | R42: https://github.com/bootstrapprx/kodoo/tree/main/modules/accounting | S42: Likely mapping; confirm exact function
A43: FN-039 | B43: Lançamentos e Diários | C43: contabil.lancamento.criar_rascunho | D43: Comando | E43: Criar lançamento em rascunho | F43: F1 | G43: Alta | H43: Planejada | I43: T-044 | J43: Não | K43: Não | O43: contabil.lancamento.create_rascunho | P43: accounting | Q43: core / journal | R43: https://github.com/bootstrapprx/kodoo/tree/main/modules/accounting | S43: Likely mapping; confirm exact function
A44: FN-040 | B44: Lançamentos e Diários | C44: contabil.lancamento.editar_rascunho | D44: Comando | E44: Editar rascunho | F44: F1 | G44: Alta | H44: Planejada | I44: T-044, T-054 | J44: Não | K44: Não | O44: contabil.lancamento.update_rascunho | P44: accounting | Q44: core / journal | R44: https://github.com/bootstrapprx/kodoo/tree/main/modules/accounting | S44: Likely mapping; confirm exact function
A45: FN-041 | B45: Lançamentos e Diários | C45: contabil.lancamento.postar | D45: Comando | E45: Postar lançamento | F45: F1 | G45: Alta | H45: Planejada | I45: T-044, T-048 | J45: Não | K45: Não | O45: contabil.lancamento.postar | P45: accounting | Q45: core / journal | R45: https://github.com/bootstrapprx/kodoo/tree/main/modules/accounting | S45: Likely mapping; confirm exact function
A46: FN-042 | B46: Lançamentos e Diários | C46: contabil.lancamento.excluir_rascunho | D46: Comando | E46: Excluir rascunho | F46: F1 | G46: Média | H46: Planejada | I46: T-044 | J46: Não | K46: Não | O46: contabil.lancamento.excluir_rascunho | P46: accounting | Q46: core / journal | R46: https://github.com/bootstrapprx/kodoo/tree/main/modules/accounting | S46: Likely mapping; confirm exact function
A47: FN-043 | B47: Lançamentos e Diários | C47: contabil.lancamento.listar | D47: Consulta | E47: Consultar lançamentos com filtros | F47: F1 | G47: Alta | H47: Planejada | I47: T-043, T-045 | J47: Não | K47: Não | O47: contabil.lancamento.list | P47: accounting | Q47: core / journal | R47: https://github.com/bootstrapprx/kodoo/tree/main/modules/accounting | S47: Likely mapping; confirm exact function
A48: FN-044 | B48: Lançamentos e Diários | C48: contabil.lancamento.estornar | D48: Comando | E48: Estornar lançamento postado | F48: F2 | G48: Alta | H48: Planejada | I48: T-046 | J48: Não | K48: Não | O48: contabil.lancamento.reverse | P48: accounting | Q48: core / journal | R48: https://github.com/bootstrapprx/kodoo/tree/main/modules/accounting | S48: Likely mapping; confirm exact function
A49: FN-045 | B49: Lançamentos e Diários | C49: contabil.saldo_inicial.lancar | D49: Comando | E49: Lançar saldos iniciais | F49: F2 | G49: Alta | H49: Planejada | I49: T-047 | J49: Não | K49: Não | O49: contabil.balance_inicial.post | P49: accounting | Q49: core / journal | R49: https://github.com/bootstrapprx/kodoo/tree/main/modules/accounting | S49: Likely mapping; confirm exact function
A50: FN-046 | B50: Lançamentos e Diários | C50: contabil.lancamento.modelo | D50: Comando | E50: Modelos e lançamentos recorrentes | F50: F3 | G50: Média | H50: Planejada | I50: T-050, T-051 | J50: Não | K50: Não | O50: contabil.lancamento.modelo | P50: accounting | Q50: core / journal | R50: https://github.com/bootstrapprx/kodoo/tree/main/modules/accounting | S50: Likely mapping; confirm exact function
A51: FN-047 | B51: Lançamentos e Diários | C51: contabil.lancamento.postar_lote | D51: Comando | E51: Postagem em lote | F51: F3 | G51: Média | H51: Planejada | I51: T-052 | J51: Não | K51: Não | O51: contabil.lancamento.postar_batch | P51: accounting | Q51: core / journal | R51: https://github.com/bootstrapprx/kodoo/tree/main/modules/accounting | S51: Likely mapping; confirm exact function
...

Sheet Arquétipos
A1: Arquétipos de tela e seus componentes
A2: Cada arquétipo precisa de uma spec no crate kodoo-view e de um componente genérico no Dioxus. Atualize os status conforme avançar.
A4: Arquétipo | B4: Família | C4: Descrição | D4: Spec (kodoo-view) | E4: Componente Dioxus | F4: Telas planejadas ou existentes | G4: Notas
A5: Dashboard | B5: Orientação | C5: Widgets que apontam para telas de projeção | D5: Em andamento | E5: Planejada | F5: =IF(A5="","",COUNTIF(Telas!$D$5:$D$400,A5))
A6: Launcher | B6: Orientação | C6: Lançador de módulos e entradas | D6: Em andamento | E6: Planejada | F6: =IF(A6="","",COUNTIF(Telas!$D$5:$D$400,A6))
A7: List | B7: Consulta | C7: Grade com filtros, ordenação e paginação | D7: Em andamento | E7: Planejada | F7: =IF(A7="","",COUNTIF(Telas!$D$5:$D$400,A7))
A8: Detail | B8: Consulta | C8: Registro somente leitura com abas relacionadas | D8: Em andamento | E8: Planejada | F8: =IF(A8="","",COUNTIF(Telas!$D$5:$D$400,A8))
A9: Calendar | B9: Consulta | C9: Itens posicionados por data | D9: Em andamento | E9: Planejada | F9: =IF(A9="","",COUNTIF(Telas!$D$5:$D$400,A9))
